[2023-11-15T15:07:26.536+0000] {logging_mixin.py:151} INFO - Changing /opt/***/logs/dag_id=data_github_to_gcs_dag/run_id=manual__2023-11-15T15:02:16.284480+00:00/task_id=process_data_task permission to 509
[2023-11-15T15:07:26.578+0000] {logging_mixin.py:151} INFO - Changing /opt/***/logs/dag_id=data_github_to_gcs_dag/run_id=manual__2023-11-15T15:02:16.284480+00:00/task_id=process_data_task permission to 509
[2023-11-15T15:07:26.684+0000] {taskinstance.py:1159} INFO - Dependencies all met for dep_context=non-requeueable deps ti=<TaskInstance: data_github_to_gcs_dag.process_data_task manual__2023-11-15T15:02:16.284480+00:00 [queued]>
[2023-11-15T15:07:26.703+0000] {taskinstance.py:1159} INFO - Dependencies all met for dep_context=requeueable deps ti=<TaskInstance: data_github_to_gcs_dag.process_data_task manual__2023-11-15T15:02:16.284480+00:00 [queued]>
[2023-11-15T15:07:26.704+0000] {taskinstance.py:1361} INFO - Starting attempt 2 of 2
[2023-11-15T15:07:26.729+0000] {taskinstance.py:1382} INFO - Executing <Task(PythonOperator): process_data_task> on 2023-11-15 15:02:16.284480+00:00
[2023-11-15T15:07:26.739+0000] {standard_task_runner.py:57} INFO - Started process 3538 to run task
[2023-11-15T15:07:26.743+0000] {standard_task_runner.py:84} INFO - Running: ['***', 'tasks', 'run', 'data_github_to_gcs_dag', 'process_data_task', 'manual__2023-11-15T15:02:16.284480+00:00', '--job-id', '99', '--raw', '--subdir', 'DAGS_FOLDER/data_github_to_gcp.py', '--cfg-path', '/tmp/tmpwe2pihof']
[2023-11-15T15:07:26.746+0000] {standard_task_runner.py:85} INFO - Job 99: Subtask process_data_task
[2023-11-15T15:07:26.759+0000] {warnings.py:109} WARNING - /home/***/.local/lib/python3.8/site-packages/***/settings.py:193: DeprecationWarning: The sql_alchemy_conn option in [core] has been moved to the sql_alchemy_conn option in [database] - the old setting has been used, but please update your config.
  SQL_ALCHEMY_CONN = conf.get("database", "SQL_ALCHEMY_CONN")

[2023-11-15T15:07:26.802+0000] {logging_mixin.py:151} INFO - Changing /opt/***/logs/dag_id=data_github_to_gcs_dag/run_id=manual__2023-11-15T15:02:16.284480+00:00/task_id=process_data_task permission to 509
[2023-11-15T15:07:26.807+0000] {task_command.py:416} INFO - Running <TaskInstance: data_github_to_gcs_dag.process_data_task manual__2023-11-15T15:02:16.284480+00:00 [running]> on host 2952db3161f1
[2023-11-15T15:07:26.901+0000] {taskinstance.py:1662} INFO - Exporting env vars: AIRFLOW_CTX_DAG_OWNER='***' AIRFLOW_CTX_DAG_ID='data_github_to_gcs_dag' AIRFLOW_CTX_TASK_ID='process_data_task' AIRFLOW_CTX_EXECUTION_DATE='2023-11-15T15:02:16.284480+00:00' AIRFLOW_CTX_TRY_NUMBER='2' AIRFLOW_CTX_DAG_RUN_ID='manual__2023-11-15T15:02:16.284480+00:00'
[2023-11-15T15:07:26.903+0000] {taskinstance.py:1937} ERROR - Task failed with exception
Traceback (most recent call last):
  File "/home/airflow/.local/lib/python3.8/site-packages/airflow/operators/python.py", line 192, in execute
    return_value = self.execute_callable()
  File "/home/airflow/.local/lib/python3.8/site-packages/airflow/operators/python.py", line 209, in execute_callable
    return self.python_callable(*self.op_args, **self.op_kwargs)
  File "/opt/airflow/dags/data_github_to_gcp.py", line 37, in process_data
    movies_df = pd.read_csv(file_path)
NameError: name 'pd' is not defined
[2023-11-15T15:07:26.919+0000] {taskinstance.py:1400} INFO - Marking task as FAILED. dag_id=data_github_to_gcs_dag, task_id=process_data_task, execution_date=20231115T150216, start_date=20231115T150726, end_date=20231115T150726
[2023-11-15T15:07:26.933+0000] {standard_task_runner.py:104} ERROR - Failed to execute job 99 for task process_data_task (name 'pd' is not defined; 3538)
[2023-11-15T15:07:26.956+0000] {local_task_job_runner.py:228} INFO - Task exited with return code 1
[2023-11-15T15:07:26.986+0000] {taskinstance.py:2778} INFO - 0 downstream tasks scheduled from follow-on schedule check
