[2023-11-15T15:02:05.544+0000] {logging_mixin.py:151} INFO - Changing /opt/***/logs/dag_id=data_github_to_gcs_dag/run_id=manual__2023-11-15T14:49:29.270388+00:00/task_id=process_data_task permission to 509
[2023-11-15T15:02:05.676+0000] {logging_mixin.py:151} INFO - Changing /opt/***/logs/dag_id=data_github_to_gcs_dag/run_id=manual__2023-11-15T14:49:29.270388+00:00/task_id=process_data_task permission to 509
[2023-11-15T15:02:05.712+0000] {taskinstance.py:1159} INFO - Dependencies all met for dep_context=non-requeueable deps ti=<TaskInstance: data_github_to_gcs_dag.process_data_task manual__2023-11-15T14:49:29.270388+00:00 [queued]>
[2023-11-15T15:02:05.728+0000] {taskinstance.py:1159} INFO - Dependencies all met for dep_context=requeueable deps ti=<TaskInstance: data_github_to_gcs_dag.process_data_task manual__2023-11-15T14:49:29.270388+00:00 [queued]>
[2023-11-15T15:02:05.729+0000] {taskinstance.py:1361} INFO - Starting attempt 2 of 2
[2023-11-15T15:02:05.753+0000] {taskinstance.py:1382} INFO - Executing <Task(PythonOperator): process_data_task> on 2023-11-15 14:49:29.270388+00:00
[2023-11-15T15:02:05.762+0000] {standard_task_runner.py:57} INFO - Started process 3313 to run task
[2023-11-15T15:02:05.765+0000] {standard_task_runner.py:84} INFO - Running: ['***', 'tasks', 'run', 'data_github_to_gcs_dag', 'process_data_task', 'manual__2023-11-15T14:49:29.270388+00:00', '--job-id', '95', '--raw', '--subdir', 'DAGS_FOLDER/data_github_to_gcp.py', '--cfg-path', '/tmp/tmpesueayao']
[2023-11-15T15:02:05.768+0000] {standard_task_runner.py:85} INFO - Job 95: Subtask process_data_task
[2023-11-15T15:02:05.783+0000] {warnings.py:109} WARNING - /home/***/.local/lib/python3.8/site-packages/***/settings.py:193: DeprecationWarning: The sql_alchemy_conn option in [core] has been moved to the sql_alchemy_conn option in [database] - the old setting has been used, but please update your config.
  SQL_ALCHEMY_CONN = conf.get("database", "SQL_ALCHEMY_CONN")

[2023-11-15T15:02:05.825+0000] {logging_mixin.py:151} INFO - Changing /opt/***/logs/dag_id=data_github_to_gcs_dag/run_id=manual__2023-11-15T14:49:29.270388+00:00/task_id=process_data_task permission to 509
[2023-11-15T15:02:05.830+0000] {task_command.py:416} INFO - Running <TaskInstance: data_github_to_gcs_dag.process_data_task manual__2023-11-15T14:49:29.270388+00:00 [running]> on host 2952db3161f1
[2023-11-15T15:02:05.933+0000] {taskinstance.py:1662} INFO - Exporting env vars: AIRFLOW_CTX_DAG_OWNER='***' AIRFLOW_CTX_DAG_ID='data_github_to_gcs_dag' AIRFLOW_CTX_TASK_ID='process_data_task' AIRFLOW_CTX_EXECUTION_DATE='2023-11-15T14:49:29.270388+00:00' AIRFLOW_CTX_TRY_NUMBER='2' AIRFLOW_CTX_DAG_RUN_ID='manual__2023-11-15T14:49:29.270388+00:00'
[2023-11-15T15:02:05.936+0000] {taskinstance.py:1937} ERROR - Task failed with exception
Traceback (most recent call last):
  File "/home/airflow/.local/lib/python3.8/site-packages/airflow/operators/python.py", line 192, in execute
    return_value = self.execute_callable()
  File "/home/airflow/.local/lib/python3.8/site-packages/airflow/operators/python.py", line 209, in execute_callable
    return self.python_callable(*self.op_args, **self.op_kwargs)
  File "/opt/airflow/dags/data_github_to_gcp.py", line 37, in process_data
    movies_df = pd.read_csv(file_path)
NameError: name 'pd' is not defined
[2023-11-15T15:02:05.951+0000] {taskinstance.py:1400} INFO - Marking task as FAILED. dag_id=data_github_to_gcs_dag, task_id=process_data_task, execution_date=20231115T144929, start_date=20231115T150205, end_date=20231115T150205
[2023-11-15T15:02:05.968+0000] {standard_task_runner.py:104} ERROR - Failed to execute job 95 for task process_data_task (name 'pd' is not defined; 3313)
[2023-11-15T15:02:06.019+0000] {local_task_job_runner.py:228} INFO - Task exited with return code 1
[2023-11-15T15:02:06.056+0000] {taskinstance.py:2778} INFO - 0 downstream tasks scheduled from follow-on schedule check
