[2023-11-17T02:22:13.051+0000] {logging_mixin.py:151} INFO - Changing /opt/***/logs/dag_id=data_github_to_gcs_dag/run_id=scheduled__2023-11-16T00:00:00+00:00/task_id=process_data_task permission to 509
[2023-11-17T02:22:13.095+0000] {logging_mixin.py:151} INFO - Changing /opt/***/logs/dag_id=data_github_to_gcs_dag/run_id=scheduled__2023-11-16T00:00:00+00:00/task_id=process_data_task permission to 509
[2023-11-17T02:22:13.204+0000] {taskinstance.py:1159} INFO - Dependencies all met for dep_context=non-requeueable deps ti=<TaskInstance: data_github_to_gcs_dag.process_data_task scheduled__2023-11-16T00:00:00+00:00 [queued]>
[2023-11-17T02:22:13.218+0000] {taskinstance.py:1159} INFO - Dependencies all met for dep_context=requeueable deps ti=<TaskInstance: data_github_to_gcs_dag.process_data_task scheduled__2023-11-16T00:00:00+00:00 [queued]>
[2023-11-17T02:22:13.219+0000] {taskinstance.py:1361} INFO - Starting attempt 2 of 2
[2023-11-17T02:22:13.234+0000] {taskinstance.py:1382} INFO - Executing <Task(PythonOperator): process_data_task> on 2023-11-16 00:00:00+00:00
[2023-11-17T02:22:13.242+0000] {standard_task_runner.py:57} INFO - Started process 14590 to run task
[2023-11-17T02:22:13.246+0000] {standard_task_runner.py:84} INFO - Running: ['***', 'tasks', 'run', 'data_github_to_gcs_dag', 'process_data_task', 'scheduled__2023-11-16T00:00:00+00:00', '--job-id', '121', '--raw', '--subdir', 'DAGS_FOLDER/data_github_to_gcp.py', '--cfg-path', '/tmp/tmpx3oqecfs']
[2023-11-17T02:22:13.249+0000] {standard_task_runner.py:85} INFO - Job 121: Subtask process_data_task
[2023-11-17T02:22:13.264+0000] {warnings.py:109} WARNING - /home/***/.local/lib/python3.8/site-packages/***/settings.py:193: DeprecationWarning: The sql_alchemy_conn option in [core] has been moved to the sql_alchemy_conn option in [database] - the old setting has been used, but please update your config.
  SQL_ALCHEMY_CONN = conf.get("database", "SQL_ALCHEMY_CONN")

[2023-11-17T02:22:13.303+0000] {logging_mixin.py:151} INFO - Changing /opt/***/logs/dag_id=data_github_to_gcs_dag/run_id=scheduled__2023-11-16T00:00:00+00:00/task_id=process_data_task permission to 509
[2023-11-17T02:22:13.308+0000] {task_command.py:416} INFO - Running <TaskInstance: data_github_to_gcs_dag.process_data_task scheduled__2023-11-16T00:00:00+00:00 [running]> on host 2952db3161f1
[2023-11-17T02:22:13.394+0000] {taskinstance.py:1662} INFO - Exporting env vars: AIRFLOW_CTX_DAG_OWNER='***' AIRFLOW_CTX_DAG_ID='data_github_to_gcs_dag' AIRFLOW_CTX_TASK_ID='process_data_task' AIRFLOW_CTX_EXECUTION_DATE='2023-11-16T00:00:00+00:00' AIRFLOW_CTX_TRY_NUMBER='2' AIRFLOW_CTX_DAG_RUN_ID='scheduled__2023-11-16T00:00:00+00:00'
[2023-11-17T02:22:13.414+0000] {taskinstance.py:1937} ERROR - Task failed with exception
Traceback (most recent call last):
  File "/home/airflow/.local/lib/python3.8/site-packages/pandas/core/indexes/base.py", line 3653, in get_loc
    return self._engine.get_loc(casted_key)
  File "pandas/_libs/index.pyx", line 147, in pandas._libs.index.IndexEngine.get_loc
  File "pandas/_libs/index.pyx", line 176, in pandas._libs.index.IndexEngine.get_loc
  File "pandas/_libs/hashtable_class_helper.pxi", line 7080, in pandas._libs.hashtable.PyObjectHashTable.get_item
  File "pandas/_libs/hashtable_class_helper.pxi", line 7088, in pandas._libs.hashtable.PyObjectHashTable.get_item
KeyError: 'YEAR'

The above exception was the direct cause of the following exception:

Traceback (most recent call last):
  File "/home/airflow/.local/lib/python3.8/site-packages/airflow/operators/python.py", line 192, in execute
    return_value = self.execute_callable()
  File "/home/airflow/.local/lib/python3.8/site-packages/airflow/operators/python.py", line 209, in execute_callable
    return self.python_callable(*self.op_args, **self.op_kwargs)
  File "/opt/airflow/dags/data_github_to_gcp.py", line 64, in process_data
    movies_df['YEAR'] = movies_df['YEAR'].apply(clean_year)
  File "/home/airflow/.local/lib/python3.8/site-packages/pandas/core/frame.py", line 3761, in __getitem__
    indexer = self.columns.get_loc(key)
  File "/home/airflow/.local/lib/python3.8/site-packages/pandas/core/indexes/base.py", line 3655, in get_loc
    raise KeyError(key) from err
KeyError: 'YEAR'
[2023-11-17T02:22:13.432+0000] {taskinstance.py:1400} INFO - Marking task as FAILED. dag_id=data_github_to_gcs_dag, task_id=process_data_task, execution_date=20231116T000000, start_date=20231117T022213, end_date=20231117T022213
[2023-11-17T02:22:13.447+0000] {standard_task_runner.py:104} ERROR - Failed to execute job 121 for task process_data_task ('YEAR'; 14590)
[2023-11-17T02:22:13.460+0000] {local_task_job_runner.py:228} INFO - Task exited with return code 1
[2023-11-17T02:22:13.496+0000] {taskinstance.py:2778} INFO - 0 downstream tasks scheduled from follow-on schedule check
